2025-07-16 17:07:00,809 ERROR: Exception on /edit_profile [POST] [in /home/oslab/microblog/venv/lib/python3.12/site-packages/flask/app.py:875]
Traceback (most recent call last):
  File "/home/oslab/microblog/venv/lib/python3.12/site-packages/sqlalchemy/engine/base.py", line 1963, in _exec_single_context
    self.dialect.do_execute(
  File "/home/oslab/microblog/venv/lib/python3.12/site-packages/sqlalchemy/engine/default.py", line 943, in do_execute
    cursor.execute(statement, parameters)
sqlite3.IntegrityError: UNIQUE constraint failed: user.username

The above exception was the direct cause of the following exception:

Traceback (most recent call last):
  File "/home/oslab/microblog/venv/lib/python3.12/site-packages/flask/app.py", line 1511, in wsgi_app
    response = self.full_dispatch_request()
               ^^^^^^^^^^^^^^^^^^^^^^^^^^^^
  File "/home/oslab/microblog/venv/lib/python3.12/site-packages/flask/app.py", line 919, in full_dispatch_request
    rv = self.handle_user_exception(e)
         ^^^^^^^^^^^^^^^^^^^^^^^^^^^^^
  File "/home/oslab/microblog/venv/lib/python3.12/site-packages/flask/app.py", line 917, in full_dispatch_request
    rv = self.dispatch_request()
         ^^^^^^^^^^^^^^^^^^^^^^^
  File "/home/oslab/microblog/venv/lib/python3.12/site-packages/flask/app.py", line 902, in dispatch_request
    return self.ensure_sync(self.view_functions[rule.endpoint])(**view_args)  # type: ignore[no-any-return]
           ^^^^^^^^^^^^^^^^^^^^^^^^^^^^^^^^^^^^^^^^^^^^^^^^^^^^^^^^^^^^^^^^^
  File "/home/oslab/microblog/venv/lib/python3.12/site-packages/flask_login/utils.py", line 290, in decorated_view
    return current_app.ensure_sync(func)(*args, **kwargs)
           ^^^^^^^^^^^^^^^^^^^^^^^^^^^^^^^^^^^^^^^^^^^^^^
  File "/home/oslab/microblog/app/routes.py", line 108, in edit_profile
    db.session.commit()
  File "/home/oslab/microblog/venv/lib/python3.12/site-packages/sqlalchemy/orm/scoping.py", line 599, in commit
    return self._proxied.commit()
           ^^^^^^^^^^^^^^^^^^^^^^
  File "/home/oslab/microblog/venv/lib/python3.12/site-packages/sqlalchemy/orm/session.py", line 2032, in commit
    trans.commit(_to_root=True)
  File "<string>", line 2, in commit
  File "/home/oslab/microblog/venv/lib/python3.12/site-packages/sqlalchemy/orm/state_changes.py", line 139, in _go
    ret_value = fn(self, *arg, **kw)
                ^^^^^^^^^^^^^^^^^^^^
  File "/home/oslab/microblog/venv/lib/python3.12/site-packages/sqlalchemy/orm/session.py", line 1313, in commit
    self._prepare_impl()
  File "<string>", line 2, in _prepare_impl
  File "/home/oslab/microblog/venv/lib/python3.12/site-packages/sqlalchemy/orm/state_changes.py", line 139, in _go
    ret_value = fn(self, *arg, **kw)
                ^^^^^^^^^^^^^^^^^^^^
  File "/home/oslab/microblog/venv/lib/python3.12/site-packages/sqlalchemy/orm/session.py", line 1288, in _prepare_impl
    self.session.flush()
  File "/home/oslab/microblog/venv/lib/python3.12/site-packages/sqlalchemy/orm/session.py", line 4345, in flush
    self._flush(objects)
  File "/home/oslab/microblog/venv/lib/python3.12/site-packages/sqlalchemy/orm/session.py", line 4480, in _flush
    with util.safe_reraise():
  File "/home/oslab/microblog/venv/lib/python3.12/site-packages/sqlalchemy/util/langhelpers.py", line 224, in __exit__
    raise exc_value.with_traceback(exc_tb)
  File "/home/oslab/microblog/venv/lib/python3.12/site-packages/sqlalchemy/orm/session.py", line 4441, in _flush
    flush_context.execute()
  File "/home/oslab/microblog/venv/lib/python3.12/site-packages/sqlalchemy/orm/unitofwork.py", line 466, in execute
    rec.execute(self)
  File "/home/oslab/microblog/venv/lib/python3.12/site-packages/sqlalchemy/orm/unitofwork.py", line 642, in execute
    util.preloaded.orm_persistence.save_obj(
  File "/home/oslab/microblog/venv/lib/python3.12/site-packages/sqlalchemy/orm/persistence.py", line 85, in save_obj
    _emit_update_statements(
  File "/home/oslab/microblog/venv/lib/python3.12/site-packages/sqlalchemy/orm/persistence.py", line 912, in _emit_update_statements
    c = connection.execute(
        ^^^^^^^^^^^^^^^^^^^
  File "/home/oslab/microblog/venv/lib/python3.12/site-packages/sqlalchemy/engine/base.py", line 1415, in execute
    return meth(
           ^^^^^
  File "/home/oslab/microblog/venv/lib/python3.12/site-packages/sqlalchemy/sql/elements.py", line 523, in _execute_on_connection
    return connection._execute_clauseelement(
           ^^^^^^^^^^^^^^^^^^^^^^^^^^^^^^^^^^
  File "/home/oslab/microblog/venv/lib/python3.12/site-packages/sqlalchemy/engine/base.py", line 1637, in _execute_clauseelement
    ret = self._execute_context(
          ^^^^^^^^^^^^^^^^^^^^^^
  File "/home/oslab/microblog/venv/lib/python3.12/site-packages/sqlalchemy/engine/base.py", line 1842, in _execute_context
    return self._exec_single_context(
           ^^^^^^^^^^^^^^^^^^^^^^^^^^
  File "/home/oslab/microblog/venv/lib/python3.12/site-packages/sqlalchemy/engine/base.py", line 1982, in _exec_single_context
    self._handle_dbapi_exception(
  File "/home/oslab/microblog/venv/lib/python3.12/site-packages/sqlalchemy/engine/base.py", line 2351, in _handle_dbapi_exception
    raise sqlalchemy_exception.with_traceback(exc_info[2]) from e
  File "/home/oslab/microblog/venv/lib/python3.12/site-packages/sqlalchemy/engine/base.py", line 1963, in _exec_single_context
    self.dialect.do_execute(
  File "/home/oslab/microblog/venv/lib/python3.12/site-packages/sqlalchemy/engine/default.py", line 943, in do_execute
    cursor.execute(statement, parameters)
sqlalchemy.exc.IntegrityError: (sqlite3.IntegrityError) UNIQUE constraint failed: user.username
[SQL: UPDATE user SET username=?, about_me=? WHERE user.id = ?]
[parameters: ('yang', 'helloï¼Œas you can see i am randy,and my full name is randy taylor,i am a new menber of this blog family,i will post my everyday learning here', 2)]
(Background on this error at: https://sqlalche.me/e/20/gkpj)
2025-07-16 17:14:16,022 INFO: Microblog startup [in /home/oslab/microblog/app/__init__.py:44]
2025-07-16 17:43:18,633 INFO: Microblog startup [in /home/oslab/microblog/app/__init__.py:44]
2025-07-18 13:53:15,506 INFO: Microblog startup [in /home/oslab/microblog/app/__init__.py:44]
2025-07-18 13:54:01,010 INFO: Microblog startup [in /home/oslab/microblog/app/__init__.py:44]
2025-07-18 13:56:23,069 INFO: Microblog startup [in /home/oslab/microblog/app/__init__.py:44]
2025-07-18 13:56:54,490 INFO: Microblog startup [in /home/oslab/microblog/app/__init__.py:44]
2025-07-18 16:02:55,289 INFO: Microblog startup [in /home/oslab/microblog/app/__init__.py:44]
2025-07-18 16:22:30,297 INFO: Microblog startup [in /home/oslab/microblog/app/__init__.py:44]
2025-07-18 17:27:48,386 INFO: Microblog startup [in /home/oslab/microblog/app/__init__.py:44]
2025-07-19 14:31:12,426 INFO: Microblog startup [in /home/oslab/microblog/app/__init__.py:44]
2025-07-19 14:44:19,707 INFO: Microblog startup [in /home/oslab/microblog/app/__init__.py:44]
2025-07-19 14:59:21,359 INFO: Microblog startup [in /home/oslab/microblog/app/__init__.py:44]
2025-07-19 14:59:25,515 ERROR: Exception on /user/susan [GET] [in /home/oslab/microblog/venv/lib/python3.12/site-packages/flask/app.py:875]
Traceback (most recent call last):
  File "/home/oslab/microblog/venv/lib/python3.12/site-packages/flask/app.py", line 1511, in wsgi_app
    response = self.full_dispatch_request()
               ^^^^^^^^^^^^^^^^^^^^^^^^^^^^
  File "/home/oslab/microblog/venv/lib/python3.12/site-packages/flask/app.py", line 919, in full_dispatch_request
    rv = self.handle_user_exception(e)
         ^^^^^^^^^^^^^^^^^^^^^^^^^^^^^
  File "/home/oslab/microblog/venv/lib/python3.12/site-packages/flask/app.py", line 917, in full_dispatch_request
    rv = self.dispatch_request()
         ^^^^^^^^^^^^^^^^^^^^^^^
  File "/home/oslab/microblog/venv/lib/python3.12/site-packages/flask/app.py", line 902, in dispatch_request
    return self.ensure_sync(self.view_functions[rule.endpoint])(**view_args)  # type: ignore[no-any-return]
           ^^^^^^^^^^^^^^^^^^^^^^^^^^^^^^^^^^^^^^^^^^^^^^^^^^^^^^^^^^^^^^^^^
  File "/home/oslab/microblog/venv/lib/python3.12/site-packages/flask_login/utils.py", line 290, in decorated_view
    return current_app.ensure_sync(func)(*args, **kwargs)
           ^^^^^^^^^^^^^^^^^^^^^^^^^^^^^^^^^^^^^^^^^^^^^^
  File "/home/oslab/microblog/app/routes.py", line 83, in user
    posts = db.session.scalars(current_user.posts()).all()
                               ^^^^^^^^^^^^^^^^^^^^
TypeError: 'WriteOnlyCollection' object is not callable
2025-07-19 15:03:09,878 INFO: Microblog startup [in /home/oslab/microblog/app/__init__.py:44]
