2025-07-20 16:28:14,043 ERROR: Exception on /reset_password_request [POST] [in /home/oslab/microblog/venv/lib/python3.12/site-packages/flask/app.py:875]
Traceback (most recent call last):
  File "/home/oslab/microblog/venv/lib/python3.12/site-packages/flask/app.py", line 1511, in wsgi_app
    response = self.full_dispatch_request()
               ^^^^^^^^^^^^^^^^^^^^^^^^^^^^
  File "/home/oslab/microblog/venv/lib/python3.12/site-packages/flask/app.py", line 919, in full_dispatch_request
    rv = self.handle_user_exception(e)
         ^^^^^^^^^^^^^^^^^^^^^^^^^^^^^
  File "/home/oslab/microblog/venv/lib/python3.12/site-packages/flask/app.py", line 917, in full_dispatch_request
    rv = self.dispatch_request()
         ^^^^^^^^^^^^^^^^^^^^^^^
  File "/home/oslab/microblog/venv/lib/python3.12/site-packages/flask/app.py", line 902, in dispatch_request
    return self.ensure_sync(self.view_functions[rule.endpoint])(**view_args)  # type: ignore[no-any-return]
           ^^^^^^^^^^^^^^^^^^^^^^^^^^^^^^^^^^^^^^^^^^^^^^^^^^^^^^^^^^^^^^^^^
  File "/home/oslab/microblog/app/routes.py", line 230, in reset_password_request
    send_password_reset_email(user)
  File "/home/oslab/microblog/app/email.py", line 13, in send_password_reset_email
    send_email('[Microblog] Reset Your Password',
  File "/home/oslab/microblog/app/email.py", line 9, in send_email
    mail.send(msg)
  File "/home/oslab/microblog/venv/lib/python3.12/site-packages/flask_mail/__init__.py", line 539, in send
    with self.connect() as connection:
  File "/home/oslab/microblog/venv/lib/python3.12/site-packages/flask_mail/__init__.py", line 127, in __enter__
    self.host = self.configure_host()
                ^^^^^^^^^^^^^^^^^^^^^
  File "/home/oslab/microblog/venv/lib/python3.12/site-packages/flask_mail/__init__.py", line 144, in configure_host
    host = smtplib.SMTP(self.mail.server, self.mail.port)
           ^^^^^^^^^^^^^^^^^^^^^^^^^^^^^^^^^^^^^^^^^^^^^^
  File "/usr/lib/python3.12/smtplib.py", line 255, in __init__
    (code, msg) = self.connect(host, port)
                  ^^^^^^^^^^^^^^^^^^^^^^^^
  File "/usr/lib/python3.12/smtplib.py", line 343, in connect
    (code, msg) = self.getreply()
                  ^^^^^^^^^^^^^^^
  File "/usr/lib/python3.12/smtplib.py", line 405, in getreply
    raise SMTPServerDisconnected("Connection unexpectedly closed")
smtplib.SMTPServerDisconnected: Connection unexpectedly closed
2025-07-20 16:33:47,374 INFO: Microblog startup [in /home/oslab/microblog/app/__init__.py:45]
2025-07-21 13:56:34,807 INFO: Microblog startup [in /home/oslab/microblog/app/__init__.py:45]
2025-07-21 13:56:42,785 ERROR: Exception on /login [GET] [in /home/oslab/microblog/venv/lib/python3.12/site-packages/flask/app.py:875]
Traceback (most recent call last):
  File "/home/oslab/microblog/venv/lib/python3.12/site-packages/flask/app.py", line 1511, in wsgi_app
    response = self.full_dispatch_request()
               ^^^^^^^^^^^^^^^^^^^^^^^^^^^^
  File "/home/oslab/microblog/venv/lib/python3.12/site-packages/flask/app.py", line 919, in full_dispatch_request
    rv = self.handle_user_exception(e)
         ^^^^^^^^^^^^^^^^^^^^^^^^^^^^^
  File "/home/oslab/microblog/venv/lib/python3.12/site-packages/flask/app.py", line 917, in full_dispatch_request
    rv = self.dispatch_request()
         ^^^^^^^^^^^^^^^^^^^^^^^
  File "/home/oslab/microblog/venv/lib/python3.12/site-packages/flask/app.py", line 902, in dispatch_request
    return self.ensure_sync(self.view_functions[rule.endpoint])(**view_args)  # type: ignore[no-any-return]
           ^^^^^^^^^^^^^^^^^^^^^^^^^^^^^^^^^^^^^^^^^^^^^^^^^^^^^^^^^^^^^^^^^
  File "/home/oslab/microblog/app/routes.py", line 68, in login
    return render_template('login.html', title='Sign In', form=form)
           ^^^^^^^^^^^^^^^^^^^^^^^^^^^^^^^^^^^^^^^^^^^^^^^^^^^^^^^^^
  File "/home/oslab/microblog/venv/lib/python3.12/site-packages/flask/templating.py", line 149, in render_template
    template = app.jinja_env.get_or_select_template(template_name_or_list)
               ^^^^^^^^^^^^^^^^^^^^^^^^^^^^^^^^^^^^^^^^^^^^^^^^^^^^^^^^^^^
  File "/home/oslab/microblog/venv/lib/python3.12/site-packages/jinja2/environment.py", line 1087, in get_or_select_template
    return self.get_template(template_name_or_list, parent, globals)
           ^^^^^^^^^^^^^^^^^^^^^^^^^^^^^^^^^^^^^^^^^^^^^^^^^^^^^^^^^
  File "/home/oslab/microblog/venv/lib/python3.12/site-packages/jinja2/environment.py", line 1016, in get_template
    return self._load_template(name, globals)
           ^^^^^^^^^^^^^^^^^^^^^^^^^^^^^^^^^^
  File "/home/oslab/microblog/venv/lib/python3.12/site-packages/jinja2/environment.py", line 975, in _load_template
    template = self.loader.load(self, name, self.make_globals(globals))
               ^^^^^^^^^^^^^^^^^^^^^^^^^^^^^^^^^^^^^^^^^^^^^^^^^^^^^^^^
  File "/home/oslab/microblog/venv/lib/python3.12/site-packages/jinja2/loaders.py", line 138, in load
    code = environment.compile(source, name, filename)
           ^^^^^^^^^^^^^^^^^^^^^^^^^^^^^^^^^^^^^^^^^^^
  File "/home/oslab/microblog/venv/lib/python3.12/site-packages/jinja2/environment.py", line 771, in compile
    self.handle_exception(source=source_hint)
  File "/home/oslab/microblog/venv/lib/python3.12/site-packages/jinja2/environment.py", line 942, in handle_exception
    raise rewrite_traceback_stack(source=source)
  File "/home/oslab/microblog/app/templates/login.html", line 36, in template
    {% block content %}
jinja2.exceptions.TemplateAssertionError: block 'content' defined twice
2025-07-21 13:56:42,873 ERROR: Exception on /favicon.ico [GET] [in /home/oslab/microblog/venv/lib/python3.12/site-packages/flask/app.py:875]
Traceback (most recent call last):
  File "/home/oslab/microblog/venv/lib/python3.12/site-packages/flask/app.py", line 917, in full_dispatch_request
    rv = self.dispatch_request()
         ^^^^^^^^^^^^^^^^^^^^^^^
  File "/home/oslab/microblog/venv/lib/python3.12/site-packages/flask/app.py", line 891, in dispatch_request
    self.raise_routing_exception(req)
  File "/home/oslab/microblog/venv/lib/python3.12/site-packages/flask/app.py", line 500, in raise_routing_exception
    raise request.routing_exception  # type: ignore[misc]
    ^^^^^^^^^^^^^^^^^^^^^^^^^^^^^^^
  File "/home/oslab/microblog/venv/lib/python3.12/site-packages/flask/ctx.py", line 362, in match_request
    result = self.url_adapter.match(return_rule=True)  # type: ignore
             ^^^^^^^^^^^^^^^^^^^^^^^^^^^^^^^^^^^^^^^^
  File "/home/oslab/microblog/venv/lib/python3.12/site-packages/werkzeug/routing/map.py", line 629, in match
    raise NotFound() from None
werkzeug.exceptions.NotFound: 404 Not Found: The requested URL was not found on the server. If you entered the URL manually please check your spelling and try again.

During handling of the above exception, another exception occurred:

Traceback (most recent call last):
  File "/home/oslab/microblog/venv/lib/python3.12/site-packages/flask/app.py", line 1511, in wsgi_app
    response = self.full_dispatch_request()
               ^^^^^^^^^^^^^^^^^^^^^^^^^^^^
  File "/home/oslab/microblog/venv/lib/python3.12/site-packages/flask/app.py", line 919, in full_dispatch_request
    rv = self.handle_user_exception(e)
         ^^^^^^^^^^^^^^^^^^^^^^^^^^^^^
  File "/home/oslab/microblog/venv/lib/python3.12/site-packages/flask/app.py", line 802, in handle_user_exception
    return self.handle_http_exception(e)
           ^^^^^^^^^^^^^^^^^^^^^^^^^^^^^
  File "/home/oslab/microblog/venv/lib/python3.12/site-packages/flask/app.py", line 777, in handle_http_exception
    return self.ensure_sync(handler)(e)  # type: ignore[no-any-return]
           ^^^^^^^^^^^^^^^^^^^^^^^^^^^^
  File "/home/oslab/microblog/app/errors.py", line 6, in not_found_error
    return render_template("404.html"),404
           ^^^^^^^^^^^^^^^^^^^^^^^^^^^
  File "/home/oslab/microblog/venv/lib/python3.12/site-packages/flask/templating.py", line 150, in render_template
    return _render(app, template, context)
           ^^^^^^^^^^^^^^^^^^^^^^^^^^^^^^^
  File "/home/oslab/microblog/venv/lib/python3.12/site-packages/flask/templating.py", line 131, in _render
    rv = template.render(context)
         ^^^^^^^^^^^^^^^^^^^^^^^^
  File "/home/oslab/microblog/venv/lib/python3.12/site-packages/jinja2/environment.py", line 1295, in render
    self.environment.handle_exception()
  File "/home/oslab/microblog/venv/lib/python3.12/site-packages/jinja2/environment.py", line 942, in handle_exception
    raise rewrite_traceback_stack(source=source)
  File "/home/oslab/microblog/app/templates/404.html", line 1, in top-level template code
    {% extends "base.html" %}
  File "/home/oslab/microblog/venv/lib/python3.12/site-packages/jinja2/environment.py", line 942, in handle_exception
    raise rewrite_traceback_stack(source=source)
  File "/home/oslab/microblog/app/templates/base.html", line 92, in template
    {% block content %}{% endblock %}
    ^^^^^^^^^^^^^^^^^^^^^^^^^
jinja2.exceptions.TemplateAssertionError: block 'content' defined twice
2025-07-21 14:06:49,752 INFO: Microblog startup [in /home/oslab/microblog/app/__init__.py:45]
2025-07-21 15:14:57,509 INFO: Microblog startup [in /home/oslab/microblog/app/__init__.py:45]
2025-07-22 16:03:55,580 INFO: Microblog startup [in /home/oslab/microblog/app/__init__.py:47]
2025-07-23 16:10:36,617 INFO: Microblog startup [in /home/oslab/microblog/app/__init__.py:58]
